<?xml version="1.0" ?>
<!-- =================================================================================== -->
<!-- |    This document was autogenerated by xacro from gem.urdf.xacro                 | -->
<!-- |    EDITING THIS FILE BY HAND IS NOT RECOMMENDED                                 | -->
<!-- =================================================================================== -->
<robot name="gem_robot">
  <!-- ######################################################################### -->
  <gazebo reference="right_fixed_hinge_link">
    <material>Gazebo/Red</material>
  </gazebo>
  <gazebo reference="left_fixed_hinge_link">
    <material>Gazebo/Red</material>
  </gazebo>
  <gazebo reference="right_steering_hinge_link">
    <mu1>10000</mu1>
    <mu2>100000000</mu2>
    <kp>1000000</kp>
    <kd>1e8</kd>
    <minDepth>0.001</minDepth>
    <maxVel>100.0</maxVel>
    <material>Gazebo/Blue</material>
  </gazebo>
  <gazebo reference="left_steering_hinge_link">
    <mu1>10000</mu1>
    <mu2>100000000</mu2>
    <kp>1000000</kp>
    <kd>1e8</kd>
    <minDepth>0.001</minDepth>
    <maxVel>100.0</maxVel>
    <material>Gazebo/Blue</material>
  </gazebo>
  <gazebo reference="front_left_wheel_link">
    <mu1>0.9</mu1>
    <mu2>1000000</mu2>
    <minDepth>0.005</minDepth>
    <kp>1e8</kp>
    <material>Gazebo/Black</material>
  </gazebo>
  <gazebo reference="front_right_wheel_link">
    <mu1>0.9</mu1>
    <mu2>1000000</mu2>
    <minDepth>0.005</minDepth>
    <kp>1e8</kp>
    <material>Gazebo/Black</material>
  </gazebo>
  <gazebo reference="rear_left_wheel_link">
    <mu1>0.9</mu1>
    <mu2>1000000</mu2>
    <minDepth>0.005</minDepth>
    <kp>1e8</kp>
    <material>Gazebo/Black</material>
  </gazebo>
  <gazebo reference="rear_right_wheel_link">
    <mu1>0.9</mu1>
    <mu2>1000000</mu2>
    <minDepth>0.005</minDepth>
    <kp>1e8</kp>
    <material>Gazebo/Black</material>
  </gazebo>
  <!-- ************************************** -->
  <!-- colors used by Gazebo -->
  <gazebo reference="base_link">
    <material>Gazebo/White</material>
  </gazebo>
  <gazebo reference="chair_link">
    <material>Gazebo/Grey</material>
  </gazebo>
  <gazebo reference="door_link">
    <material>Gazebo/White</material>
  </gazebo>
  <gazebo reference="front_camera_link">
    <material>Gazebo/Black</material>
  </gazebo>
  <gazebo reference="front_rack_link">
    <material>Gazebo/Black</material>
  </gazebo>
  <gazebo reference="rear_rack_link">
    <material>Gazebo/Black</material>
  </gazebo>
  <gazebo reference="top_rack_link">
    <material>Gazebo/Black</material>
  </gazebo>
  <gazebo reference="front_left_emergency_button_link">
    <material>Gazebo/Red</material>
  </gazebo>
  <gazebo reference="front_right_emergency_button_link">
    <material>Gazebo/Red</material>
  </gazebo>
  <gazebo reference="rear_left_emergency_button_link">
    <material>Gazebo/Red</material>
  </gazebo>
  <gazebo reference="rear_right_emergency_button_link">
    <material>Gazebo/Red</material>
  </gazebo>
  <gazebo reference="rear_left_light_link">
    <material>Gazebo/Red</material>
  </gazebo>
  <gazebo reference="rear_right_light_link">
    <material>Gazebo/Red</material>
  </gazebo>
  <gazebo reference="rear_light_bar_link">
    <material>Gazebo/Red</material>
  </gazebo>
  <gazebo reference="front_left_head_light_link">
    <material>Gazebo/White</material>
  </gazebo>
  <gazebo reference="front_left_head_light_link">
    <material>Gazebo/White</material>
  </gazebo>
  <gazebo reference="front_left_turn_light_link">
    <material>Gazebo/Orange</material>
  </gazebo>
  <gazebo reference="front_right_turn_light_link">
    <material>Gazebo/Orange</material>
  </gazebo>
  <gazebo reference="left_I_link">
    <material>Gazebo/Orange</material>
  </gazebo>
  <gazebo reference="right_I_link">
    <material>Gazebo/Orange</material>
  </gazebo>
  <gazebo reference="left_blue_outer_link">
    <material>Gazebo/Blue</material>
  </gazebo>
  <gazebo reference="right_blue_outer_link">
    <material>Gazebo/Blue</material>
  </gazebo>
  <gazebo reference="left_antenna_link">
    <material>Gazebo/Grey</material>
  </gazebo>
  <gazebo reference="right_antenna_link">
    <material>Gazebo/Grey</material>
  </gazebo>
  <gazebo reference="rear_left_stop_light_link">
    <material>Gazebo/Red</material>
  </gazebo>
  <gazebo reference="rear_right_stop_light_link">
    <material>Gazebo/Red</material>
  </gazebo>
  <gazebo reference="front_single_camera_link">
    <material>Gazebo/Red</material>
  </gazebo>
  <gazebo reference="IMU_link">
    <material>Gazebo/Red</material>
  </gazebo>
  <gazebo reference="front_sonar_link">
    <material>Gazebo/Orange</material>
  </gazebo>
  <gazebo reference="rear_sonar_link">
    <material>Gazebo/Orange</material>
  </gazebo>
  <gazebo reference="stereo_camera_link">
    <material>Gazebo/Red</material>
  </gazebo>
  <gazebo>
    <plugin filename="libgazebo_ros_control.so" name="gazebo_ros_control">
      <legacyModeNS>true</legacyModeNS>
      <robotSimType>gazebo_ros_control/DefaultRobotHWSim</robotSimType>
    </plugin>
  </gazebo>
  <!-- ***************************** camera ***************************** -->
  <gazebo reference="front_single_camera_link">
    <sensor name="front_single_camera_sensor" type="camera">
      <update_rate>30.0</update_rate>
      <camera name="front_single_camera">
        <horizontal_fov>1.5707963</horizontal_fov>
        <image>
          <width>960</width>
          <height>540</height>
          <format>R8G8B8</format>
        </image>
        <clip>
          <near>0.02</near>
          <far>300</far>
        </clip>
        <noise>
          <type>gaussian</type>
          <mean>0.0</mean>
          <stddev>0.007</stddev>
        </noise>
      </camera>
      <plugin filename="libgazebo_ros_camera.so" name="front_single_camera_controller">
        <alwaysOn>true</alwaysOn>
        <updateRate>0.0</updateRate>
        <cameraName>front_single_camera</cameraName>
        <imageTopicName>image_raw</imageTopicName>
        <cameraInfoTopicName>camera_info</cameraInfoTopicName>
        <frameName>front_single_camera_link</frameName>
        <hackBaseline>0.07</hackBaseline>
        <distortionK1>0.0</distortionK1>
        <distortionK2>0.0</distortionK2>
        <distortionK3>0.0</distortionK3>
        <distortionT1>0.0</distortionT1>
        <distortionT2>0.0</distortionT2>
      </plugin>
    </sensor>
  </gazebo>
  <!-- ***************************** IMU ***************************** -->
  <gazebo reference="IMU_link">
    <gravity>true</gravity>
    <sensor name="imu_sensor" type="imu">
      <always_on>true</always_on>
      <update_rate>100</update_rate>
      <visualize>true</visualize>
      <topic>__default_topic__</topic>
      <plugin filename="libgazebo_ros_imu_sensor.so" name="imu_plugin">
        <topicName>imu</topicName>
        <bodyName>IMU_link</bodyName>
        <updateRateHZ>20.0</updateRateHZ>
        <gaussianNoise>0.0</gaussianNoise>
        <xyzOffset>0 0 0</xyzOffset>
        <rpyOffset>0 0 0</rpyOffset>
        <frameName>IMU_link</frameName>
        <initialOrientationAsReference>false</initialOrientationAsReference>
      </plugin>
      <pose>0 0 0 0 0 0</pose>
    </sensor>
  </gazebo>
  <!-- ***************************** GPS ***************************** -->
  <gazebo>
    <plugin filename="libhector_gazebo_ros_gps.so" name="gazebo_ros_gps">
      <updateRate>20.0</updateRate>
      <bodyName>GPS_link</bodyName>
      <frameId>GPS_link</frameId>
      <topicName>gps/fix</topicName>
      <velocityTopicName>gps/fix_velocity</velocityTopicName>
      <referenceLatitude>40.09302494</referenceLatitude>
      <referenceLongitude>-88.23575484</referenceLongitude>
      <referenceAltitude>220</referenceAltitude>
      <referenceHeading>90</referenceHeading>
      <!--
    <offset>0 0 0</offset>
    <drift>0.001 0.001 0.001</drift>
    <gaussianNoise>0.05 0.05 0.05</gaussianNoise>
    <velocityDrift>0.001 0.001 0.001</velocityDrift>
    <velocityGaussianNoise>0.5 0.5 0.5</velocityGaussianNoise>
    -->
      <offset>0 0 0</offset>
      <drift>0.001 0.001 0.001</drift>
      <gaussianNoise>0.01 0.01 0.01</gaussianNoise>
      <velocityDrift>0 0 0</velocityDrift>
      <velocityGaussianNoise>0.05 0.05 0.05</velocityGaussianNoise>
    </plugin>
  </gazebo>
  <!-- ***************************** Front Sonar ***************************** -->
  <gazebo reference="front_sonar_link">
    <sensor name="front_sonar_sensor" type="ray">
      <always_on>true</always_on>
      <update_rate>10</update_rate>
      <pose>0 0 0 0 0 0</pose>
      <visualize>false</visualize>
      <ray>
        <scan>
          <horizontal>
            <samples>2</samples>
            <resolution>1</resolution>
            <min_angle>-28</min_angle>
            <max_angle>28</max_angle>
          </horizontal>
          <vertical>
            <samples>2</samples>
            <resolution>1</resolution>
            <min_angle>-28</min_angle>
            <max_angle>28</max_angle>
          </vertical>
        </scan>
        <range>
          <min>0.3</min>
          <max>5</max>
          <resolution>0.01</resolution>
        </range>
      </ray>
      <plugin filename="libhector_gazebo_ros_sonar.so" name="gazebo_ros_sonar_controller">
        <gaussianNoise>0.005</gaussianNoise>
        <topicName>front_sonar_distance</topicName>
        <frameId>front_sonar_link</frameId>
      </plugin>
    </sensor>
  </gazebo>
  <!-- ***************************** Rear Sonar ***************************** -->
  <gazebo reference="rear_sonar_link">
    <sensor name="rear_sonar_sensor" type="ray">
      <always_on>true</always_on>
      <update_rate>10</update_rate>
      <pose>0 0 0 0 0 0</pose>
      <visualize>false</visualize>
      <ray>
        <scan>
          <horizontal>
            <samples>2</samples>
            <resolution>1</resolution>
            <min_angle>-28</min_angle>
            <max_angle>28</max_angle>
          </horizontal>
          <vertical>
            <samples>2</samples>
            <resolution>1</resolution>
            <min_angle>-28</min_angle>
            <max_angle>28</max_angle>
          </vertical>
        </scan>
        <range>
          <min>0.3</min>
          <max>5</max>
          <resolution>0.01</resolution>
        </range>
      </ray>
      <plugin filename="libhector_gazebo_ros_sonar.so" name="gazebo_ros_sonar_controller">
        <gaussianNoise>0.005</gaussianNoise>
        <topicName>rear_sonar_distance</topicName>
        <frameId>rear_sonar_link</frameId>
      </plugin>
    </sensor>
  </gazebo>
  <!-- ***************************** stereo camera ***************************** -->
  <gazebo reference="stereo_camera_link">
    <sensor name="stereo_camera" type="multicamera">
      <update_rate>30.0</update_rate>
      <camera name="left">
        <horizontal_fov>1.5707963</horizontal_fov>
        <image>
          <width>800</width>
          <height>600</height>
          <format>R8G8B8</format>
        </image>
        <clip>
          <near>0.02</near>
          <far>300</far>
        </clip>
        <noise>
          <type>gaussian</type>
          <mean>0.0</mean>
          <stddev>0.007</stddev>
        </noise>
      </camera>
      <camera name="right">
        <pose>0 -0.07 0 0 0 0</pose>
        <horizontal_fov>1.5707963</horizontal_fov>
        <image>
          <width>800</width>
          <height>600</height>
          <format>R8G8B8</format>
        </image>
        <clip>
          <near>0.02</near>
          <far>300</far>
        </clip>
        <noise>
          <type>gaussian</type>
          <mean>0.0</mean>
          <stddev>0.007</stddev>
        </noise>
      </camera>
      <plugin filename="libgazebo_ros_multicamera.so" name="stereo_camera_controller">
        <alwaysOn>true</alwaysOn>
        <updateRate>0.0</updateRate>
        <cameraName>stereo/camera</cameraName>
        <imageTopicName>image_raw</imageTopicName>
        <cameraInfoTopicName>camera_info</cameraInfoTopicName>
        <frameName>stereo_camera_link</frameName>
        <!--<rightFrameName>right_camera_optical_frame</rightFrameName>-->
        <!-- <hackBaseline>0.07</hackBaseline> -->
        <hackBaseline>0.5</hackBaseline>
        <distortionK1>0.0</distortionK1>
        <distortionK2>0.0</distortionK2>
        <distortionK3>0.0</distortionK3>
        <distortionT1>0.0</distortionT1>
        <distortionT2>0.0</distortionT2>
      </plugin>
    </sensor>
  </gazebo>
  <!-- Sensor providing ground truth Odometry of base_link -->
  <gazebo>
    <plugin filename="libgazebo_ros_p3d.so" name="ground_truth">
      <updateRate>30.0</updateRate>
      <frameName>/world</frameName>
      <!-- Frame of reference is the global coordinates -->
      <bodyName>base_footprint</bodyName>
      <topicName>base_footprint/odom</topicName>
    </plugin>
  </gazebo>
  <!-- colors used by Rviz -->
  <material name="black">
    <color rgba="0.0 0.0 0.0 1.0"/>
  </material>
  <material name="blue">
    <color rgba="0 0 0.8 1.0"/>
  </material>
  <material name="green">
    <color rgba="0.0 0.8 0.0 1.0"/>
  </material>
  <material name="grey">
    <color rgba="0.2 0.2 0.2 1.0"/>
  </material>
  <material name="orange">
    <color rgba="1.0 0.4235294117647059 0.0392156862745098 1.0"/>
  </material>
  <material name="brown">
    <color rgba="0.8705882352941177 0.8117647058823529 0.7647058823529411 1.0"/>
  </material>
  <material name="red">
    <color rgba="0.8 0.0 0.0 1.0"/>
  </material>
  <material name="white">
    <color rgba="1.0 1.0 1.0 1.0"/>
  </material>
  <!-- transmission macros -->
  <!-- ******************************************** Transmissions ********************************************* -->
  <transmission name="rear_left_wheel_transmission" type="SimpleTransmission">
    <type>transmission_interface/SimpleTransmission</type>
    <joint name="rear_left_wheel_joint">
      <hardwareInterface>hardware_interface/EffortJointInterface</hardwareInterface>
    </joint>
    <actuator name="rear_left_wheel_motor">
      <hardwareInterface>hardware_interface/EffortJointInterface</hardwareInterface>
      <mechanicalReduction>1</mechanicalReduction>
    </actuator>
  </transmission>
  <transmission name="rear_right_wheel_transmission" type="SimpleTransmission">
    <type>transmission_interface/SimpleTransmission</type>
    <joint name="rear_right_wheel_joint">
      <hardwareInterface>hardware_interface/EffortJointInterface</hardwareInterface>
    </joint>
    <actuator name="rear_right_wheel_motor">
      <hardwareInterface>hardware_interface/EffortJointInterface</hardwareInterface>
      <mechanicalReduction>1</mechanicalReduction>
    </actuator>
  </transmission>
  <transmission name="front_left_wheel_transmission" type="SimpleTransmission">
    <type>transmission_interface/SimpleTransmission</type>
    <joint name="front_left_wheel_joint">
      <hardwareInterface>hardware_interface/EffortJointInterface</hardwareInterface>
    </joint>
    <actuator name="front_left_wheel_motor">
      <hardwareInterface>hardware_interface/EffortJointInterface</hardwareInterface>
      <mechanicalReduction>1</mechanicalReduction>
    </actuator>
  </transmission>
  <transmission name="front_right_wheel_transmission" type="SimpleTransmission">
    <type>transmission_interface/SimpleTransmission</type>
    <joint name="front_right_wheel_joint">
      <hardwareInterface>hardware_interface/EffortJointInterface</hardwareInterface>
    </joint>
    <actuator name="front_right_wheel_motor">
      <hardwareInterface>hardware_interface/EffortJointInterface</hardwareInterface>
      <mechanicalReduction>1</mechanicalReduction>
    </actuator>
  </transmission>
  <transmission name="left_steering_hinge_transmission" type="SimpleTransmission">
    <type>transmission_interface/SimpleTransmission</type>
    <joint name="left_steering_hinge_joint">
      <hardwareInterface>hardware_interface/EffortJointInterface</hardwareInterface>
    </joint>
    <actuator name="left_steering_hinge_motor">
      <hardwareInterface>hardware_interface/EffortJointInterface</hardwareInterface>
      <mechanicalReduction>1</mechanicalReduction>
    </actuator>
  </transmission>
  <transmission name="right_steering_hinge_transmission" type="SimpleTransmission">
    <type>transmission_interface/SimpleTransmission</type>
    <joint name="right_steering_hinge_joint">
      <hardwareInterface>hardware_interface/EffortJointInterface</hardwareInterface>
    </joint>
    <actuator name="right_steering_hinge_motor">
      <hardwareInterface>hardware_interface/EffortJointInterface</hardwareInterface>
      <mechanicalReduction>1</mechanicalReduction>
    </actuator>
  </transmission>
  <!-- ******************************************** Base link below ******************************************* -->
  <link name="base_footprint">
  </link>
  <link name="base_link">
  </link>
  <link name="center_link">
    <inertial>
      <origin rpy="0 0 0" xyz="0 0 0"/>
      <!--
      <mass value="686.066668067387" />
      <inertia
        ixx="205.702789313137"
        ixy="-0.20742120719075"
        ixz="-9.13771633467953"
        iyy="482.020173559149"
        iyz="0.0517191981605489"
        izz="482.316418870047" />
      -->
      <mass value="686"/>
      <inertia ixx="325" ixy="0" ixz="0" iyy="597" iyz="0" izz="465"/>
    </inertial>
    <visual>
      <origin rpy="0 0 0" xyz="0 0 0"/>
      <geometry>
        <mesh filename="package://gem_description/meshes/base_link.STL"/>
      </geometry>
      <material name="white"/>
    </visual>
    <collision>
      <origin rpy="0 0 0" xyz="0 0 0"/>
      <geometry>
        <!--
        <box size="0.1 0.1 0.1"/>
        -->
        <mesh filename="package://gem_description/meshes/base_link.STL"/>
      </geometry>
    </collision>
  </link>
  <!-- ***************************************** Set vehicle load point ***************************************** -->
  <joint name="base_link" type="fixed">
    <origin rpy="0 0 0" xyz="0 0 0.44"/>
    <parent link="base_footprint"/>
    <child link="base_link"/>
  </joint>
  <joint name="center_link" type="fixed">
    <origin rpy="0 0 0" xyz="0.87 0 0.151"/>
    <parent link="base_link"/>
    <child link="center_link"/>
  </joint>
  <!-- ******************************************* Fixed links below ******************************************* -->
  <link name="chair_link">
    <inertial>
      <origin rpy="0 0 0" xyz="0 0 0"/>
      <mass value="0"/>
      <inertia ixx="0" ixy="0" ixz="0" iyy="0" iyz="0" izz="0"/>
    </inertial>
    <visual>
      <origin rpy="0 0 0" xyz="0 0 0"/>
      <geometry>
        <mesh filename="package://gem_description/meshes/chair_link.STL"/>
      </geometry>
      <material name="grey"/>
    </visual>
    <collision>
      <origin rpy="0 0 0" xyz="0 0 0"/>
      <geometry>
        <mesh filename="package://gem_description/meshes/chair_link.STL"/>
      </geometry>
    </collision>
  </link>
  <joint name="chair_joint" type="fixed">
    <origin rpy="0 0 0" xyz="0.001 0 -0.02"/>
    <parent link="center_link"/>
    <child link="chair_link"/>
    <axis xyz="0 0 0"/>
  </joint>
  <link name="door_link">
    <inertial>
      <origin rpy="0 0 0" xyz="0 0 0"/>
      <mass value="0"/>
      <inertia ixx="0" ixy="0" ixz="0" iyy="0" iyz="0" izz="0"/>
    </inertial>
    <visual>
      <origin rpy="0 0 0" xyz="0 0 0"/>
      <geometry>
        <mesh filename="package://gem_description/meshes/door_link.STL"/>
      </geometry>
      <material name="white"/>
    </visual>
    <collision>
      <origin rpy="0 0 0" xyz="0 0 0"/>
      <geometry>
        <mesh filename="package://gem_description/meshes/door_link.STL"/>
      </geometry>
    </collision>
  </link>
  <joint name="door_joint" type="fixed">
    <origin rpy="0 0 0" xyz="0.001 0 -0.015"/>
    <parent link="center_link"/>
    <child link="door_link"/>
    <axis xyz="0 0 0"/>
  </joint>
  <link name="top_rack_link">
    <inertial>
      <origin rpy="0 0 0" xyz="0 0 0"/>
      <mass value="0"/>
      <inertia ixx="0" ixy="0" ixz="0" iyy="0" iyz="0" izz="0"/>
    </inertial>
    <visual>
      <origin rpy="0 0 0" xyz="0 0 0"/>
      <geometry>
        <mesh filename="package://gem_description/meshes/top_rack_link.STL"/>
      </geometry>
      <material name="black"/>
    </visual>
    <collision>
      <origin rpy="0 0 0" xyz="0 0 0"/>
      <geometry>
        <mesh filename="package://gem_description/meshes/top_rack_link.STL"/>
      </geometry>
    </collision>
  </link>
  <joint name="top_rack_joint" type="fixed">
    <origin rpy="1.5708 0 3.1416" xyz="-0.10172 0.6575 1.3921"/>
    <parent link="center_link"/>
    <child link="top_rack_link"/>
    <axis xyz="0 0 0"/>
  </joint>
  <link name="front_rack_link">
    <inertial>
      <origin rpy="0 0 0" xyz="0 0 0"/>
      <mass value="0"/>
      <inertia ixx="0." ixy="0" ixz="0" iyy="0" iyz="0" izz="0"/>
    </inertial>
    <visual>
      <origin rpy="0 0 0" xyz="0 0 0"/>
      <geometry>
        <mesh filename="package://gem_description/meshes/front_rack_link.STL"/>
      </geometry>
      <material name="black"/>
    </visual>
    <collision>
      <origin rpy="0 0 0" xyz="0 0 0"/>
      <geometry>
        <mesh filename="package://gem_description/meshes/front_rack_link.STL"/>
      </geometry>
    </collision>
  </link>
  <joint name="front_rack_joint" type="fixed">
    <origin rpy="1.5708 0 1.5708" xyz="1.352 0 -0.30594"/>
    <parent link="center_link"/>
    <child link="front_rack_link"/>
    <axis xyz="0 0 0"/>
  </joint>
  <link name="rear_rack_link">
    <inertial>
      <origin rpy="0 0 0" xyz="0 0 0"/>
      <mass value="0"/>
      <inertia ixx="0" ixy="0" ixz="0" iyy="0" iyz="0" izz="0"/>
    </inertial>
    <visual>
      <origin rpy="0 0 0" xyz="0 0 0"/>
      <geometry>
        <mesh filename="package://gem_description/meshes/rear_rack_link.STL"/>
      </geometry>
      <material name="black"/>
    </visual>
    <collision>
      <origin rpy="0 0 0" xyz="0 0 0"/>
      <geometry>
        <mesh filename="package://gem_description/meshes/rear_rack_link.STL"/>
      </geometry>
    </collision>
  </link>
  <joint name="rear_rack_joint" type="fixed">
    <origin rpy="1.5708 0 -1.5708" xyz="-1.302 0 -0.27168"/>
    <parent link="center_link"/>
    <child link="rear_rack_link"/>
    <axis xyz="0 0 0"/>
  </joint>
  <link name="front_right_head_light_link">
    <inertial>
      <origin rpy="0 0 0" xyz="0 0 0"/>
      <mass value="0"/>
      <inertia ixx="0" ixy="0" ixz="0" iyy="0" iyz="0" izz="0"/>
    </inertial>
    <visual>
      <origin rpy="0 0 0" xyz="0 0 0"/>
      <geometry>
        <mesh filename="package://gem_description/meshes/front_right_head_light_link.STL"/>
      </geometry>
      <material name="white"/>
    </visual>
    <collision>
      <origin rpy="0 0 0" xyz="0 0 0"/>
      <geometry>
        <mesh filename="package://gem_description/meshes/front_right_head_light_link.STL"/>
      </geometry>
    </collision>
  </link>
  <joint name="front_right_head_light_joint" type="fixed">
    <origin rpy="0 0 0" xyz="0.755 -0.5 0.58706"/>
    <parent link="center_link"/>
    <child link="front_right_head_light_link"/>
    <axis xyz="1 0 0"/>
  </joint>
  <link name="front_left_head_light_link">
    <inertial>
      <origin rpy="0 0 0" xyz="0 0 0"/>
      <mass value="0"/>
      <inertia ixx="0" ixy="0" ixz="0" iyy="0" iyz="0" izz="0"/>
    </inertial>
    <visual>
      <origin rpy="0 0 0" xyz="0 0 0"/>
      <geometry>
        <mesh filename="package://gem_description/meshes/front_left_head_light_link.STL"/>
      </geometry>
      <material name="white"/>
    </visual>
    <collision>
      <origin rpy="0 0 0" xyz="0 0 0"/>
      <geometry>
        <mesh filename="package://gem_description/meshes/front_left_head_light_link.STL"/>
      </geometry>
    </collision>
  </link>
  <joint name="front_left_head_light_joint" type="fixed">
    <origin rpy="0 0 0" xyz="0.755 0.5 0.58706"/>
    <parent link="center_link"/>
    <child link="front_left_head_light_link"/>
    <axis xyz="1 0 0"/>
  </joint>
  <link name="front_right_turn_light_link">
    <inertial>
      <origin rpy="0 0 0" xyz="0 0 0"/>
      <mass value="0"/>
      <inertia ixx="0" ixy="0" ixz="0" iyy="0" iyz="0" izz="0"/>
    </inertial>
    <visual>
      <origin rpy="0 0 0" xyz="0 0 0"/>
      <geometry>
        <mesh filename="package://gem_description/meshes/front_right_turn_light_link.STL"/>
      </geometry>
      <material name="orange"/>
    </visual>
    <collision>
      <origin rpy="0 0 0" xyz="0 0 0"/>
      <geometry>
        <mesh filename="package://gem_description/meshes/front_right_turn_light_link.STL"/>
      </geometry>
    </collision>
  </link>
  <joint name="front_right_turn_light_joint" type="fixed">
    <origin rpy="0 0 0" xyz="0.765 -0.345 0.58706"/>
    <parent link="center_link"/>
    <child link="front_right_turn_light_link"/>
    <axis xyz="1 0 0"/>
  </joint>
  <link name="front_left_turn_light_link">
    <inertial>
      <origin rpy="0 0 0" xyz="0 0 0"/>
      <mass value="0"/>
      <inertia ixx="0" ixy="0" ixz="0" iyy="0" iyz="0" izz="0"/>
    </inertial>
    <visual>
      <origin rpy="0 0 0" xyz="0 0 0"/>
      <geometry>
        <mesh filename="package://gem_description/meshes/front_left_turn_light_link.STL"/>
      </geometry>
      <material name="orange"/>
    </visual>
    <collision>
      <origin rpy="0 0 0" xyz="0 0 0"/>
      <geometry>
        <mesh filename="package://gem_description/meshes/front_left_turn_light_link.STL"/>
      </geometry>
    </collision>
  </link>
  <joint name="front_left_turn_light_joint" type="fixed">
    <origin rpy="0 0 0" xyz="0.765 0.345 0.58706"/>
    <parent link="center_link"/>
    <child link="front_left_turn_light_link"/>
    <axis xyz="1 0 0"/>
  </joint>
  <link name="rear_right_light_link">
    <inertial>
      <origin rpy="0 0 0" xyz="0 0 0"/>
      <mass value="0"/>
      <inertia ixx="0" ixy="0" ixz="0" iyy="0" iyz="0" izz="0"/>
    </inertial>
    <visual>
      <origin rpy="0 0 0" xyz="0 0 0"/>
      <geometry>
        <mesh filename="package://gem_description/meshes/rear_right_light_link.STL"/>
      </geometry>
      <material name="red"/>
    </visual>
    <collision>
      <origin rpy="0 0 0" xyz="0 0 0"/>
      <geometry>
        <mesh filename="package://gem_description/meshes/rear_right_light_link.STL"/>
      </geometry>
    </collision>
  </link>
  <joint name="rear_right_light_joint" type="fixed">
    <origin rpy="0 0 0" xyz="-1.195 -0.32 0.025063"/>
    <parent link="center_link"/>
    <child link="rear_right_light_link"/>
    <axis xyz="1 0 0"/>
  </joint>
  <link name="rear_left_light_link">
    <inertial>
      <origin rpy="0 0 0" xyz="0 0 0"/>
      <mass value="0"/>
      <inertia ixx="0" ixy="0" ixz="0" iyy="0" iyz="0" izz="0"/>
    </inertial>
    <visual>
      <origin rpy="0 0 0" xyz="0 0 0"/>
      <geometry>
        <mesh filename="package://gem_description/meshes/rear_left_light_link.STL"/>
      </geometry>
      <material name="red"/>
    </visual>
    <collision>
      <origin rpy="0 0 0" xyz="0 0 0"/>
      <geometry>
        <mesh filename="package://gem_description/meshes/rear_left_light_link.STL"/>
      </geometry>
    </collision>
  </link>
  <joint name="rear_left_light_joint" type="fixed">
    <origin rpy="0 0 0" xyz="-1.195 0.32 0.025063"/>
    <parent link="center_link"/>
    <child link="rear_left_light_link"/>
    <axis xyz="1 0 0"/>
  </joint>
  <link name="rear_left_stop_light_link">
    <inertial>
      <origin rpy="0 0 0" xyz="0 0 0"/>
      <mass value="0"/>
      <inertia ixx="0" ixy="0" ixz="0" iyy="0" iyz="0" izz="0"/>
    </inertial>
    <visual>
      <origin rpy="0 0 0" xyz="0 0 0"/>
      <geometry>
        <mesh filename="package://gem_description/meshes/rear_left_stop_light_link.STL"/>
      </geometry>
      <material name="red"/>
    </visual>
    <collision>
      <origin rpy="0 0 0" xyz="0 0 0"/>
      <geometry>
        <mesh filename="package://gem_description/meshes/rear_left_stop_light_link.STL"/>
      </geometry>
    </collision>
  </link>
  <joint name="rear_left_stop_light_joint" type="fixed">
    <origin rpy="0 0 3.1416" xyz="-1.195 0.38 0.24506"/>
    <parent link="center_link"/>
    <child link="rear_left_stop_light_link"/>
    <axis xyz="1 0 0"/>
  </joint>
  <link name="rear_right_stop_light_link">
    <inertial>
      <origin rpy="0 0 0" xyz="0 0 0"/>
      <mass value="0"/>
      <inertia ixx="0" ixy="0" ixz="0" iyy="0" iyz="0" izz="0"/>
    </inertial>
    <visual>
      <origin rpy="0 0 0" xyz="0 0 0"/>
      <geometry>
        <mesh filename="package://gem_description/meshes/rear_right_stop_light_link.STL"/>
      </geometry>
      <material name="red"/>
    </visual>
    <collision>
      <origin rpy="0 0 0" xyz="0 0 0"/>
      <geometry>
        <mesh filename="package://gem_description/meshes/rear_right_stop_light_link.STL"/>
      </geometry>
    </collision>
  </link>
  <joint name="rear_right_stop_light_joint" type="fixed">
    <origin rpy="0 0 3.1416" xyz="-1.195 -0.38 0.24506"/>
    <parent link="center_link"/>
    <child link="rear_right_stop_light_link"/>
    <axis xyz="1 0 0"/>
  </joint>
  <link name="right_blue_outer_link">
    <inertial>
      <origin rpy="0 0 0" xyz="0 0 0"/>
      <mass value="0"/>
      <inertia ixx="0" ixy="0" ixz="0" iyy="0" iyz="0" izz="0"/>
    </inertial>
    <visual>
      <origin rpy="0 0 0" xyz="0 0 0"/>
      <geometry>
        <mesh filename="package://gem_description/meshes/right_blue_outer_link.STL"/>
      </geometry>
      <material name="blue"/>
    </visual>
    <collision>
      <origin rpy="0 0 0" xyz="0 0 0"/>
      <geometry>
        <mesh filename="package://gem_description/meshes/right_blue_outer_link.STL"/>
      </geometry>
    </collision>
  </link>
  <joint name="right_blue_outer_joint" type="fixed">
    <origin rpy="0 0 0" xyz="0.002 -0.6745 0.23435"/>
    <parent link="center_link"/>
    <child link="right_blue_outer_link"/>
    <axis xyz="0 0 0"/>
  </joint>
  <link name="right_I_link">
    <inertial>
      <origin rpy="0 0 0" xyz="0 0 0"/>
      <mass value="0"/>
      <inertia ixx="0" ixy="0" ixz="0" iyy="0" iyz="0" izz="0"/>
    </inertial>
    <visual>
      <origin rpy="0 0 0" xyz="0 0 0"/>
      <geometry>
        <mesh filename="package://gem_description/meshes/right_I_link.STL"/>
      </geometry>
      <material name="orange"/>
    </visual>
    <collision>
      <origin rpy="0 0 0" xyz="0 0 0"/>
      <geometry>
        <mesh filename="package://gem_description/meshes/right_I_link.STL"/>
      </geometry>
    </collision>
  </link>
  <joint name="right_I_joint" type="fixed">
    <origin rpy="0 0 0" xyz="0.002 -0.6745 0.23435"/>
    <parent link="center_link"/>
    <child link="right_I_link"/>
    <axis xyz="0 0 0"/>
  </joint>
  <link name="left_blue_outer_link">
    <inertial>
      <origin rpy="0 0 0" xyz="0 0 0"/>
      <mass value="0"/>
      <inertia ixx="0" ixy="0" ixz="0" iyy="0" iyz="0" izz="0"/>
    </inertial>
    <visual>
      <origin rpy="0 0 0" xyz="0 0 0"/>
      <geometry>
        <mesh filename="package://gem_description/meshes/left_blue_outer_link.STL"/>
      </geometry>
      <material name="blue"/>
    </visual>
    <collision>
      <origin rpy="0 0 0" xyz="0 0 0"/>
      <geometry>
        <mesh filename="package://gem_description/meshes/left_blue_outer_link.STL"/>
      </geometry>
    </collision>
  </link>
  <joint name="left_blue_outer_joint" type="fixed">
    <origin rpy="0 0 0" xyz="0.002 0.6645 0.23435"/>
    <parent link="center_link"/>
    <child link="left_blue_outer_link"/>
    <axis xyz="0 0 0"/>
  </joint>
  <link name="left_I_link">
    <inertial>
      <origin rpy="0 0 0" xyz="0 0 0"/>
      <mass value="0"/>
      <inertia ixx="0" ixy="0" ixz="0" iyy="0" iyz="0" izz="0"/>
    </inertial>
    <visual>
      <origin rpy="0 0 0" xyz="0 0 0"/>
      <geometry>
        <mesh filename="package://gem_description/meshes/left_I_link.STL"/>
      </geometry>
      <material name="orange"/>
    </visual>
    <collision>
      <origin rpy="0 0 0" xyz="0 0 0"/>
      <geometry>
        <mesh filename="package://gem_description/meshes/left_I_link.STL"/>
      </geometry>
    </collision>
  </link>
  <joint name="left_I_joint" type="fixed">
    <origin rpy="0 0 0" xyz="0.002 0.6645 0.23435"/>
    <parent link="center_link"/>
    <child link="left_I_link"/>
    <axis xyz="0 0 0"/>
  </joint>
  <link name="right_antenna_link">
    <inertial>
      <origin rpy="0 0 0" xyz="0 0 0"/>
      <mass value="0"/>
      <inertia ixx="0" ixy="0" ixz="0" iyy="0" iyz="0" izz="0"/>
    </inertial>
    <visual>
      <origin rpy="0 0 0" xyz="0 0 0"/>
      <geometry>
        <mesh filename="package://gem_description/meshes/right_antenna_link.STL"/>
      </geometry>
      <material name="grey"/>
    </visual>
    <collision>
      <origin rpy="0 0 0" xyz="0 0 0"/>
      <geometry>
        <mesh filename="package://gem_description/meshes/right_antenna_link.STL"/>
      </geometry>
    </collision>
  </link>
  <joint name="right_antenna_joint" type="fixed">
    <origin rpy="0 0 0" xyz="-0.23472 -0.6125 1.5071"/>
    <parent link="center_link"/>
    <child link="right_antenna_link"/>
    <axis xyz="0 0 1"/>
  </joint>
  <link name="left_antenna_link">
    <inertial>
      <origin rpy="0 0 0" xyz="0 0 0"/>
      <mass value="0"/>
      <inertia ixx="0" ixy="0" ixz="0" iyy="0" iyz="0" izz="0"/>
    </inertial>
    <visual>
      <origin rpy="0 0 0" xyz="0 0 0"/>
      <geometry>
        <mesh filename="package://gem_description/meshes/left_antenna_link.STL"/>
      </geometry>
      <material name="grey"/>
    </visual>
    <collision>
      <origin rpy="0 0 0" xyz="0 0 0"/>
      <geometry>
        <mesh filename="package://gem_description/meshes/left_antenna_link.STL"/>
      </geometry>
    </collision>
  </link>
  <joint name="left_antenna_joint" type="fixed">
    <origin rpy="0 0 0" xyz="-0.23472 0.6125 1.5071"/>
    <parent link="center_link"/>
    <child link="left_antenna_link"/>
    <axis xyz="0 0 1"/>
  </joint>
  <link name="rear_left_emergency_button_link">
    <inertial>
      <origin rpy="0 0 0" xyz="0 0 0"/>
      <mass value="0"/>
      <inertia ixx="0" ixy="0" ixz="0" iyy="0" iyz="0" izz="0"/>
    </inertial>
    <visual>
      <origin rpy="0 0 0" xyz="0 0 0"/>
      <geometry>
        <mesh filename="package://gem_description/meshes/rear_left_emergency_button_link.STL"/>
      </geometry>
      <material name="red"/>
    </visual>
    <collision>
      <origin rpy="0 0 0" xyz="0 0 0"/>
      <geometry>
        <mesh filename="package://gem_description/meshes/rear_left_emergency_button_link.STL"/>
      </geometry>
    </collision>
  </link>
  <joint name="rear_left_emergency_button_joint" type="fixed">
    <origin rpy="0 0 0" xyz="-0.72012 0.6645 0.83815"/>
    <parent link="center_link"/>
    <child link="rear_left_emergency_button_link"/>
    <axis xyz="0 1 0"/>
  </joint>
  <link name="rear_right_emergency_button_link">
    <inertial>
      <origin rpy="0 0 0" xyz="0 0 0"/>
      <mass value="0"/>
      <inertia ixx="0" ixy="0" ixz="0" iyy="0" iyz="0" izz="0"/>
    </inertial>
    <visual>
      <origin rpy="0 0 0" xyz="0 0 0"/>
      <geometry>
        <mesh filename="package://gem_description/meshes/rear_right_emergency_button_link.STL"/>
      </geometry>
      <material name="red"/>
    </visual>
    <collision>
      <origin rpy="0 0 0" xyz="0 0 0"/>
      <geometry>
        <mesh filename="package://gem_description/meshes/rear_right_emergency_button_link.STL"/>
      </geometry>
    </collision>
  </link>
  <joint name="rear_right_emergency_button_joint" type="fixed">
    <origin rpy="0 0.57871 3.1416" xyz="-0.72012 -0.6645 0.83815"/>
    <parent link="center_link"/>
    <child link="rear_right_emergency_button_link"/>
    <axis xyz="0 1 0"/>
  </joint>
  <link name="front_left_emergency_button_link">
    <inertial>
      <origin rpy="0 0 0" xyz="0 0 0"/>
      <mass value="0"/>
      <inertia ixx="0" ixy="0" ixz="0" iyy="0" iyz="0" izz="0"/>
    </inertial>
    <visual>
      <origin rpy="0 0 0" xyz="0 0 0"/>
      <geometry>
        <mesh filename="package://gem_description/meshes/front_left_emergency_button_link.STL"/>
      </geometry>
      <material name="red"/>
    </visual>
    <collision>
      <origin rpy="0 0 0" xyz="0 0 0"/>
      <geometry>
        <mesh filename="package://gem_description/meshes/front_left_emergency_button_link.STL"/>
      </geometry>
    </collision>
  </link>
  <joint name="front_left_emergency_button_joint" type="fixed">
    <origin rpy="0 0 0" xyz="1.1497 0.6645 0.20492"/>
    <parent link="center_link"/>
    <child link="front_left_emergency_button_link"/>
    <axis xyz="0 1 0"/>
  </joint>
  <link name="front_right_emergency_button_link">
    <inertial>
      <origin rpy="0 0 0" xyz="0 0 0"/>
      <mass value="0"/>
      <inertia ixx="0" ixy="0" ixz="0" iyy="0" iyz="0" izz="0"/>
    </inertial>
    <visual>
      <origin rpy="0 0 0" xyz="0 0 0"/>
      <geometry>
        <mesh filename="package://gem_description/meshes/front_right_emergency_button_link.STL"/>
      </geometry>
      <material name="red"/>
    </visual>
    <collision>
      <origin rpy="0 0 0" xyz="0 0 0"/>
      <geometry>
        <mesh filename="package://gem_description/meshes/front_right_emergency_button_link.STL"/>
      </geometry>
    </collision>
  </link>
  <joint name="front_right_emergency_button_joint" type="fixed">
    <origin rpy="0 0.57871 3.1416" xyz="1.1497 -0.6645 0.20492"/>
    <parent link="center_link"/>
    <child link="front_right_emergency_button_link"/>
    <axis xyz="0 1 0"/>
  </joint>
  <link name="rear_light_bar_link">
    <inertial>
      <origin rpy="0 0 0" xyz="0 0 0"/>
      <mass value="0"/>
      <inertia ixx="0" ixy="0" ixz="0" iyy="0" iyz="0" izz="0"/>
    </inertial>
    <visual>
      <origin rpy="0 0 0" xyz="0 0 0"/>
      <geometry>
        <mesh filename="package://gem_description/meshes/rear_light_bar_link.STL"/>
      </geometry>
      <material name="red"/>
    </visual>
    <collision>
      <origin rpy="0 0 0" xyz="0 0 0"/>
      <geometry>
        <mesh filename="package://gem_description/meshes/rear_light_bar_link.STL"/>
      </geometry>
    </collision>
  </link>
  <joint name="rear_light_bar_joint" type="fixed">
    <origin rpy="-1.9138 0 1.5708" xyz="-0.64921 0 0.76944"/>
    <parent link="center_link"/>
    <child link="rear_light_bar_link"/>
    <axis xyz="0 0 0"/>
  </joint>
  <!-- ******************************************* Fixed links above ******************************************* -->
  <!-- ***************************************** Wheel settings below ****************************************** -->
  <link name="left_steering_hinge_link">
    <inertial>
      <mass value="1"/>
      <origin rpy="0 0 0" xyz="0 0 0"/>
      <inertia ixx="0.004" ixy="0.0" ixz="0.0" iyy="0.004" iyz="0.0" izz="0.004"/>
    </inertial>
  </link>
  <link name="right_steering_hinge_link">
    <inertial>
      <mass value="1"/>
      <origin rpy="0 0 0" xyz="0 0 0"/>
      <inertia ixx="0.004" ixy="0.0" ixz="0.0" iyy="0.004" iyz="0.0" izz="0.004"/>
    </inertial>
  </link>
  <!-- ************************ Front and Rear Wheels ************************ -->
  <link name="front_left_wheel_link">
    <inertial>
      <mass value="11"/>
      <origin xyz="0 0 0"/>
      <inertia ixx="0.38291" ixy="0.0" ixz="0.0" iyy="0.38291" iyz="0.0" izz="0.38291"/>
    </inertial>
    <visual>
      <origin rpy="0 0 0" xyz="0 0 0"/>
      <geometry>
        <mesh filename="package://gem_description/meshes/front_left_wheel_link.STL"/>
      </geometry>
      <material name="black"/>
    </visual>
    <collision>
      <origin rpy="0 0 0" xyz="0 0 0"/>
      <geometry>
        <sphere radius="0.295"/>
      </geometry>
    </collision>
  </link>
  <link name="front_right_wheel_link">
    <inertial>
      <mass value="11"/>
      <origin xyz="0 0 0"/>
      <inertia ixx="0.38291" ixy="0.0" ixz="0.0" iyy="0.38291" iyz="0.0" izz="0.38291"/>
    </inertial>
    <visual>
      <origin rpy="0 0 0" xyz="0 0 0"/>
      <geometry>
        <mesh filename="package://gem_description/meshes/front_right_wheel_link.STL"/>
      </geometry>
      <material name="black"/>
    </visual>
    <collision>
      <origin rpy="0 0 0" xyz="0 0 0"/>
      <geometry>
        <sphere radius="0.295"/>
      </geometry>
    </collision>
  </link>
  <link name="rear_left_wheel_link">
    <inertial>
      <mass value="11"/>
      <origin xyz="0 0 0"/>
      <inertia ixx="0.38291" ixy="0.0" ixz="0.0" iyy="0.38291" iyz="0.0" izz="0.38291"/>
    </inertial>
    <visual>
      <origin rpy="0 0 0" xyz="0 0 0"/>
      <geometry>
        <mesh filename="package://gem_description/meshes/rear_left_wheel_link.STL"/>
      </geometry>
      <material name="black"/>
    </visual>
    <collision>
      <origin rpy="0 0 0" xyz="0 0 0"/>
      <geometry>
        <sphere radius="0.295"/>
      </geometry>
    </collision>
  </link>
  <link name="rear_right_wheel_link">
    <inertial>
      <mass value="11"/>
      <origin xyz="0 0 0"/>
      <inertia ixx="0.38291" ixy="0.0" ixz="0.0" iyy="0.38291" iyz="0.0" izz="0.38291"/>
    </inertial>
    <visual>
      <origin rpy="0 0 0" xyz="0 0 0"/>
      <geometry>
        <mesh filename="package://gem_description/meshes/rear_right_wheel_link.STL"/>
      </geometry>
      <material name="black"/>
    </visual>
    <collision>
      <origin rpy="0 0 0" xyz="0 0 0"/>
      <geometry>
        <sphere radius="0.295"/>
      </geometry>
    </collision>
  </link>
  <!-- **************************************************************************** -->
  <joint name="left_steering_hinge_joint" type="revolute">
    <parent link="center_link"/>
    <child link="left_steering_hinge_link"/>
    <origin rpy="0 0 0" xyz="0.88 0.6 -0.151"/>
    <axis xyz="0 0 1"/>
    <limit effort="100" lower="-0.61" upper="0.61" velocity="0.5"/>
  </joint>
  <joint name="right_steering_hinge_joint" type="revolute">
    <parent link="center_link"/>
    <child link="right_steering_hinge_link"/>
    <origin rpy="0 0 0" xyz="0.88 -0.6 -0.151"/>
    <axis xyz="0 0 1"/>
    <limit effort="100" lower="-0.61" upper="0.61" velocity="0.5"/>
  </joint>
  <joint name="front_left_wheel_joint" type="continuous">
    <parent link="left_steering_hinge_link"/>
    <child link="front_left_wheel_link"/>
    <origin rpy="0 0 0" xyz="0 0 0"/>
    <axis xyz="0 1 0"/>
    <limit effort="1000" velocity="100.0"/>
    <!--
    <dynamics damping="0.01"/>
    <limit effort="10000" velocity="1000"/>
    <joint_properties damping="10" friction="10.0"/>
    -->
  </joint>
  <joint name="front_right_wheel_joint" type="continuous">
    <parent link="right_steering_hinge_link"/>
    <child link="front_right_wheel_link"/>
    <origin rpy="0 0 0" xyz="0 0 0"/>
    <axis xyz="0 1 0"/>
    <limit effort="1000" velocity="100.0"/>
  </joint>
  <joint name="rear_left_wheel_joint" type="continuous">
    <origin rpy="0 0 0" xyz="-0.87 0.6 -0.151"/>
    <axis xyz="0 1 0"/>
    <parent link="center_link"/>
    <child link="rear_left_wheel_link"/>
    <limit effort="1000" velocity="100.0"/>
  </joint>
  <joint name="rear_right_wheel_joint" type="continuous">
    <origin rpy="0 0 0" xyz="-0.87 -0.6 -0.151"/>
    <axis xyz="0 1 0"/>
    <parent link="center_link"/>
    <child link="rear_right_wheel_link"/>
    <limit effort="1000" velocity="100.0"/>
  </joint>
  <!-- *********************************************** Sensors ************************************************ -->
  <!-- ************************** Top LiDAR ************************** -->
  <!-- ************************* Front Laser ************************* -->
  <!-- ************************* Front Camera ************************* -->
  <link name="front_single_camera_link">
    <collision>
      <origin rpy="0 0 0" xyz="0 0 0"/>
      <geometry>
        <box size="0.05 0.05 0.05"/>
      </geometry>
    </collision>
    <visual>
      <origin rpy="0 0 0" xyz="0 0 0"/>
      <geometry>
        <box size="0.05 0.05 0.05"/>
      </geometry>
      <material name="red"/>
    </visual>
    <inertial>
      <mass value="1e-5"/>
      <origin rpy="0 0 0" xyz="0 0 0"/>
      <inertia ixx="1e-6" ixy="0" ixz="0" iyy="1e-6" iyz="0" izz="1e-6"/>
    </inertial>
  </link>
  <joint name="gem_front_camera_joint" type="fixed">
    <origin rpy="0 0 0" xyz="0.43 0 1.19"/>
    <parent link="center_link"/>
    <child link="front_single_camera_link"/>
  </joint>
  <!-- ************************ Stereo Camera ************************ -->
  <!--

  <link name="stereo_camera_link">
    <collision>
      <origin xyz="0 0 0" rpy="0 0 0"/>
      <geometry>
        <box size="0.05 0.05 0.05"/>
      </geometry>
    </collision>
    <visual>
      <origin xyz="0 0 0" rpy="0 0 0"/>
      <geometry>
        <box size="0.05 0.05 0.05"/>
      </geometry>
      <material name="red"/>
    </visual>
    <inertial>
      <mass value="1e-5" />
      <origin xyz="0 0 0" rpy="0 0 0"/>
      <inertia ixx="1e-6" ixy="0" ixz="0" iyy="1e-6" iyz="0" izz="1e-6" />
    </inertial>
  </link>


  <joint name="gem_stereo_camera_joint" type="fixed">
    <origin xyz="-0.045 0 0" rpy="-1.5708 3.1416 0"/>
    <parent link="front_camera_link"/>
    <child link="stereo_camera_link"/>
  </joint>

  -->
  <!-- ***************************** IMU ***************************** -->
  <link name="IMU_link">
    <collision>
      <origin rpy="0 0 0" xyz="0 0 0"/>
      <geometry>
        <box size="0.1 0.1 0.1"/>
      </geometry>
    </collision>
    <visual>
      <origin rpy="0 0 0" xyz="0 0 0"/>
      <geometry>
        <box size="0.1 0.1 0.1"/>
      </geometry>
      <material name="red"/>
    </visual>
    <inertial>
      <origin rpy="0 0 0" xyz="0 0 0"/>
      <mass value="1"/>
      <inertia ixx="1.0" ixy="0.0" ixz="0.0" iyy="1.0" iyz="0.0" izz="1.0"/>
    </inertial>
  </link>
  <joint name="IMU_joint" type="fixed">
    <!--
    <origin xyz="-0.210 0 0.05" rpy="0 0 -1.5708"/>
    -->
    <origin rpy="0 0 0" xyz="-0.210 0 0.05"/>
    <parent link="center_link"/>
    <child link="IMU_link"/>
  </joint>
  <!-- ***************************** GPS ***************************** -->
  <link name="GPS_link">
    <collision>
      <origin rpy="0 0 0" xyz="0 0 0"/>
      <geometry>
        <box size="0.1 0.1 0.1"/>
      </geometry>
    </collision>
    <visual>
      <origin rpy="0 0 0" xyz="0 0 0"/>
      <geometry>
        <box size="0.1 0.1 0.1"/>
      </geometry>
      <material name="red"/>
    </visual>
    <inertial>
      <origin rpy="0 0 0" xyz="0 0 0"/>
      <mass value="1"/>
      <inertia ixx="1.0" ixy="0.0" ixz="0.0" iyy="1.0" iyz="0.0" izz="1.0"/>
    </inertial>
  </link>
  <joint name="GPS_joint" type="fixed">
    <origin rpy="0 0 0" xyz="-0.210 0 0.05"/>
    <parent link="center_link"/>
    <child link="GPS_link"/>
  </joint>
  <!-- ************************* Front Sonar ************************* -->
  <!--

  <link name="front_sonar_link">
    <inertial>
      <mass value="0.001" />
      <origin xyz="0 0 0" rpy="0 0 0" />
      <inertia ixx="0.000000017" ixy="0" ixz="0" iyy="0.000000017" iyz="0" izz="0.000000017" />
    </inertial>
    <visual>
      <origin xyz="0 0 0" rpy="0 0 0" />
      <geometry>
        <box size="0.05 0.2 0.1" />
      </geometry>
    <material name="orange"/>
    </visual>
    <collision>
      <origin xyz="0 0 0" rpy="0 0 0" />
      <geometry>
        <box size="0.05 0.2 0.1" />
      </geometry>
    </collision>
  </link>

  <joint name="front_sonar_joint" type="fixed">
    <origin xyz="0 0.38 0.065" rpy="0 -1.5708 -1.5708"/>
    <parent link="front_rack_link"/>
    <child link="front_sonar_link"/>
  </joint>

  -->
  <!-- ************************* Rear Sonar ************************** -->
  <link name="rear_sonar_link">
    <inertial>
      <mass value="0.001"/>
      <origin rpy="0 0 0" xyz="0 0 0"/>
      <inertia ixx="0.000000017" ixy="0" ixz="0" iyy="0.000000017" iyz="0" izz="0.000000017"/>
    </inertial>
    <visual>
      <origin rpy="0 0 0" xyz="0 0 0"/>
      <geometry>
        <box size="0.05 0.2 0.1"/>
      </geometry>
      <material name="orange"/>
    </visual>
    <collision>
      <origin rpy="0 0 0" xyz="0 0 0"/>
      <geometry>
        <box size="0.05 0.2 0.1"/>
      </geometry>
    </collision>
  </link>
  <joint name="rear_sonar_joint" type="fixed">
    <origin rpy="0 -1.5708 -1.5708" xyz="0 0.38 0.065"/>
    <parent link="rear_rack_link"/>
    <child link="rear_sonar_link"/>
  </joint>
  <!-- *************************************************************** -->
</robot>
